<?xml version="1.0" encoding="utf-8"?>
<!-- =================================================================================== -->
<!-- |    This document was autogenerated by xacro from comar_base.xacro               | -->
<!-- |    EDITING THIS FILE BY HAND IS NOT RECOMMENDED                                 | -->
<!-- =================================================================================== -->
<!--
  COMAR ROBOT ASELSAN 

  COMMENTED PARTS ARE USED FOR GAZEBOSIM
-->
<robot name="comar">
  <!--[Ns/m] -->
  <!-- [kg] -->
  <!--[N] -->
  <link name="comar/base_link"> </link>
  <joint name="comar/base_joint" type="fixed">
    <origin rpy="0 0 0" xyz="0 0 0"/>
    <parent link="comar/base_link"/>
    <child link="comar/base_link_inertia"/>
  </joint>
  <link name="comar/base_link_inertia">
    <inertial>
      <mass value="18.596"/>
      <!-- [kg] -->
      <origin rpy="0 0 0" xyz="0 0 0"/>
      <inertia ixx="144005e-6" ixy="254013e-6" ixz="-1667.22e-6" iyy="380679e-6" iyz="1300.96e-6" izz="447682e-6"/>
    </inertial>
    <visual>
      <origin rpy="0 0 0" xyz="0 0 0"/>
      <geometry>
        <mesh filename="file://$(find quadruped_description)/meshes/aselsan/ROBOT_GOVDE.stl"/>
      </geometry>
    </visual>
    <collision>
      <origin rpy="0 0 0" xyz="0 0 0"/>
      <geometry>
        <mesh filename="file://$(find quadruped_description)/meshes/aselsan/ROBOT_GOVDE.stl"/>
      </geometry>
    </collision>
  </link>
  <!-- ================================================_LEG 1 - FR_======================================================== -->
  <joint name="comar/abad_1_joint" type="revolute">
    <limit effort="1000" lower="-3.1415" upper="3.1415" velocity="1000"/>
    <dynamics damping="0.03" friction="0.05"/>
    <origin rpy="1.5707845 0 1.5707845" xyz="222.50e-3 -65.50e-3 0"/>
    <axis xyz="0 0 1"/>
    <parent link="comar/base_link"/>
    <child link="comar/abad_1"/>
  </joint>
  <link name="comar/abad_1">
    <inertial>
      <origin xyz="7.729e-3 4.8783e-3 -11.3664e-3"/>
      <mass value="0.8602"/>
      <!-- [kg] -->
      <inertia ixx="825001e-6" ixy="191012e-6" ixz="-799995e-6" iyy="998292e-6" iyz="485664e-6" izz="1292.28e-6"/>
    </inertial>
    <visual>
      <origin rpy="0 0 0" xyz="0 0 0"/>
      <geometry>
        <mesh filename="file://$(find quadruped_description)/meshes/aselsan/ROBOT_ABDUCTION_FR.stl"/>
      </geometry>
    </visual>
    <collision>
      <origin rpy="0 0 0" xyz="0 0 0"/>
      <geometry>
        <mesh filename="file://$(find quadruped_description)/meshes/aselsan/ROBOT_ABDUCTION_FR.stl"/>
      </geometry>
    </collision>
  </link>
  <joint name="comar/hip_1_joint" type="revolute">
    <limit effort="1000" lower="-3.1415" upper="3.1415" velocity="1000"/>
    <dynamics damping="0.03" friction="0.05"/>
    <origin rpy="1.5707845 -1.5707845 1.5707845" xyz="-15.5e-3 0 76.75e-3"/>
    <axis xyz="0 0 1"/>
    <parent link="comar/abad_1"/>
    <child link="comar/hip_1"/>
  </joint>
  <link name="comar/hip_1">
    <inertial>
      <origin xyz="26.4228e-3 3.0919e-3 54.0237e-3"/>
      <mass value="1.3625"/>
      <inertia ixx="5507.92e-6" ixy="-510892e-6" ixz="-2820.18e-6" iyy="10901.5e-6" iyz="-348021e-6" izz="6784.8e-6"/>
    </inertial>
    <visual>
      <origin rpy="0 0 0" xyz="0 0 0"/>
      <geometry>
        <mesh filename="file://$(find quadruped_description)/meshes/aselsan/ROBOT_HIP_R.stl"/>
      </geometry>
    </visual>
    <collision>
      <origin rpy="0 0 0" xyz="0 0 0"/>
      <geometry>
        <mesh filename="file://$(find quadruped_description)/meshes/aselsan/ROBOT_HIP_R.stl"/>
      </geometry>
    </collision>
  </link>
  <joint name="comar/knee_1_joint" type="revolute">
    <limit effort="0" lower="-3.1415" upper="3.1415" velocity="1000"/>
    <dynamics damping="0.03" friction="0.05"/>
    <origin rpy="0 0 0" xyz="200e-3 0 -80.24e-3"/>
    <axis xyz="0 0 1"/>
    <parent link="comar/hip_1"/>
    <child link="comar/knee_1"/>
  </joint>
  <link name="comar/knee_1">
    <inertial>
      <origin xyz="138.023e-3 -7.0815e-3 0.9002e-3"/>
      <mass value="0.2967"/>
      <inertia ixx="71342e-6" ixy="294298e-6" ixz="-46.48e-6" iyy="7209.04e-6" iyz="2007e-6" izz="7242.60e-6"/>
    </inertial>
    <visual>
      <origin rpy="0 0 0" xyz="0 0 0"/>
      <geometry>
        <mesh filename="file://$(find quadruped_description)/meshes/aselsan/ROBOT_KNEE.stl"/>
      </geometry>
    </visual>
    <collision>
      <origin rpy="0 0 0" xyz="0 0 0"/>
      <geometry>
        <mesh filename="file://$(find quadruped_description)/meshes/aselsan/ROBOT_KNEE.stl"/>
      </geometry>
    </collision>
  </link>
  <!-- ================================================_LEG 2 - FL_======================================================== -->
  <joint name="comar/abad_2_joint" type="revolute">
    <limit effort="1000" lower="-3.1415" upper="3.1415" velocity="1000"/>
    <dynamics damping="0.03" friction="0.05"/>
    <origin rpy="1.5707845 0 1.5707845" xyz="222.50e-3 65.50e-3 0"/>
    <axis xyz="0 0 1"/>
    <parent link="comar/base_link"/>
    <child link="comar/abad_2"/>
  </joint>
  <link name="comar/abad_2">
    <inertial>
      <origin xyz="7.729e-3 4.8783e-3 -11.3664e-3"/>
      <mass value="0.8602"/>
      <!-- [kg] -->
      <inertia ixx="825001e-6" ixy="-191012e-6" ixz="799995e-6" iyy="998292e-6" iyz="485664e-6" izz="1292.28e-6"/>
    </inertial>
    <visual>
      <origin rpy="0 0 0" xyz="0 0 0"/>
      <geometry>
        <mesh filename="file://$(find quadruped_description)/meshes/aselsan/ROBOT_ABDUCTION_FL.stl"/>
      </geometry>
    </visual>
    <collision>
      <origin rpy="0 0 0" xyz="0 0 0"/>
      <geometry>
        <mesh filename="file://$(find quadruped_description)/meshes/aselsan/ROBOT_ABDUCTION_FL.stl"/>
      </geometry>
    </collision>
  </link>
  <joint name="comar/hip_2_joint" type="revolute">
    <limit effort="1000" lower="-3.1415" upper="3.1415" velocity="1000"/>
    <dynamics damping="0.03" friction="0.05"/>
    <origin rpy="1.5707845 -1.5707845 1.5707845" xyz="15.5e-3 0 76.75e-3"/>
    <axis xyz="0 0 1"/>
    <parent link="comar/abad_2"/>
    <child link="comar/hip_2"/>
  </joint>
  <link name="comar/hip_2">
    <inertial>
      <origin xyz="26.4228e-3 3.0919e-3 54.0237e-3"/>
      <mass value="1.3625"/>
      <inertia ixx="5507.92e-6" ixy="-510892e-6" ixz="2820.18e-6" iyy="10901.5e-6" iyz="348021e-6" izz="6784.8e-6"/>
    </inertial>
    <visual>
      <origin rpy="0 0 0" xyz="0 0 0"/>
      <geometry>
        <mesh filename="file://$(find quadruped_description)/meshes/aselsan/ROBOT_HIP_L.stl"/>
      </geometry>
    </visual>
    <collision>
      <origin rpy="0 0 0" xyz="0 0 0"/>
      <geometry>
        <mesh filename="file://$(find quadruped_description)/meshes/aselsan/ROBOT_HIP_L.stl"/>
      </geometry>
    </collision>
  </link>
  <joint name="comar/knee_2_joint" type="revolute">
    <limit effort="0" lower="-3.1415" upper="3.1415" velocity="1000"/>
    <dynamics damping="0.03" friction="0.05"/>
    <origin rpy="0 0 0" xyz="200e-3 0 80.24e-3"/>
    <axis xyz="0 0 1"/>
    <parent link="comar/hip_2"/>
    <child link="comar/knee_2"/>
  </joint>
  <link name="comar/knee_2">
    <inertial>
      <origin xyz="138.023e-3 -7.0815e-3 0.9002e-3"/>
      <mass value="0.2967"/>
      <inertia ixx="71342e-6" ixy="294298e-6" ixz="-46.48e-6" iyy="7209.04e-6" iyz="2007e-6" izz="7242.60e-6"/>
    </inertial>
    <visual>
      <origin rpy="0 0 0" xyz="0 0 0"/>
      <geometry>
        <mesh filename="file://$(find quadruped_description)/meshes/aselsan/ROBOT_KNEE.stl"/>
      </geometry>
    </visual>
    <collision>
      <origin rpy="0 0 0" xyz="0 0 0"/>
      <geometry>
        <mesh filename="file://$(find quadruped_description)/meshes/aselsan/ROBOT_KNEE.stl"/>
      </geometry>
    </collision>
  </link>
  <!-- ================================================_LEG 3 - HR_======================================================== -->
  <joint name="comar/abad_3_joint" type="revolute">
    <limit effort="1000" lower="-3.1415" upper="3.1415" velocity="1000"/>
    <dynamics damping="0.03" friction="0.05"/>
    <origin rpy="1.5707845 0 1.5707845" xyz="-222.50e-3 -65.50e-3 0"/>
    <axis xyz="0 0 1"/>
    <parent link="comar/base_link"/>
    <child link="comar/abad_3"/>
  </joint>
  <link name="comar/abad_3">
    <inertial>
      <origin xyz="7.729e-3 4.8783e-3 -11.3664e-3"/>
      <mass value="0.8602"/>
      <!-- [kg] -->
      <inertia ixx="825001e-6" ixy="-191012e-6" ixz="-799995e-6" iyy="998292e-6" iyz="-485664e-6" izz="1292.28e-6"/>
    </inertial>
    <visual>
      <origin rpy="0 0 0" xyz="0 0 0"/>
      <geometry>
        <mesh filename="file://$(find quadruped_description)/meshes/aselsan/ROBOT_ABDUCTION_HR.stl"/>
      </geometry>
    </visual>
    <collision>
      <origin rpy="0 0 0" xyz="0 0 0"/>
      <geometry>
        <mesh filename="file://$(find quadruped_description)/meshes/aselsan/ROBOT_ABDUCTION_HR.stl"/>
      </geometry>
    </collision>
  </link>
  <joint name="comar/hip_3_joint" type="revolute">
    <limit effort="1000" lower="-3.1415" upper="3.1415" velocity="1000"/>
    <dynamics damping="0.03" friction="0.05"/>
    <origin rpy="1.5707845 -1.5707845 1.5707845" xyz="-15.5e-3 0 -76.75e-3"/>
    <axis xyz="0 0 1"/>
    <parent link="comar/abad_3"/>
    <child link="comar/hip_3"/>
  </joint>
  <link name="comar/hip_3">
    <inertial>
      <origin xyz="26.4228e-3 3.0919e-3 54.0237e-3"/>
      <mass value="1.3625"/>
      <inertia ixx="5507.92e-6" ixy="-510892e-6" ixz="-2820.18e-6" iyy="10901.5e-6" iyz="-348021e-6" izz="6784.8e-6"/>
    </inertial>
    <visual>
      <origin rpy="0 0 0" xyz="0 0 0"/>
      <geometry>
        <mesh filename="file://$(find quadruped_description)/meshes/aselsan/ROBOT_HIP_R.stl"/>
      </geometry>
    </visual>
    <collision>
      <origin rpy="0 0 0" xyz="0 0 0"/>
      <geometry>
        <mesh filename="file://$(find quadruped_description)/meshes/aselsan/ROBOT_HIP_R.stl"/>
      </geometry>
    </collision>
  </link>
  <joint name="comar/knee_3_joint" type="revolute">
    <limit effort="0" lower="-3.1415" upper="3.1415" velocity="1000"/>
    <dynamics damping="0.03" friction="0.05"/>
    <origin rpy="0 0 0" xyz="200e-3 0 -80.24e-3"/>
    <axis xyz="0 0 1"/>
    <parent link="comar/hip_3"/>
    <child link="comar/knee_3"/>
  </joint>
  <link name="comar/knee_3">
    <inertial>
      <origin xyz="138.023e-3 -7.0815e-3 0.9002e-3"/>
      <mass value="0.2967"/>
      <inertia ixx="71342e-6" ixy="294298e-6" ixz="-46.48e-6" iyy="7209.04e-6" iyz="2007e-6" izz="7242.60e-6"/>
    </inertial>
    <visual>
      <origin rpy="0 0 0" xyz="0 0 0"/>
      <geometry>
        <mesh filename="file://$(find quadruped_description)/meshes/aselsan/ROBOT_KNEE.stl"/>
      </geometry>
    </visual>
    <collision>
      <origin rpy="0 0 0" xyz="0 0 0"/>
      <geometry>
        <mesh filename="file://$(find quadruped_description)/meshes/aselsan/ROBOT_KNEE.stl"/>
      </geometry>
    </collision>
  </link>
  <!-- ================================================_LEG 4 - HL_======================================================== -->
  <joint name="comar/abad_4_joint" type="revolute">
    <limit effort="1000" lower="-3.1415" upper="3.1415" velocity="1000"/>
    <dynamics damping="0.03" friction="0.05"/>
    <origin rpy="1.5707845 0 1.5707845" xyz="-222.50e-3 65.50e-3 0"/>
    <axis xyz="0 0 1"/>
    <parent link="comar/base_link"/>
    <child link="comar/abad_4"/>
  </joint>
  <link name="comar/abad_4">
    <inertial>
      <origin xyz="7.729e-3 4.8783e-3 -11.3664e-3"/>
      <mass value="0.8602"/>
      <!-- [kg] -->
      <inertia ixx="825001e-6" ixy="191012e-6" ixz="799995e-6" iyy="998292e-6" iyz="-485664e-6" izz="1292.28e-6"/>
    </inertial>
    <visual>
      <origin rpy="0 0 0" xyz="0 0 0"/>
      <geometry>
        <mesh filename="file://$(find quadruped_description)/meshes/aselsan/ROBOT_ABDUCTION_HL.stl"/>
      </geometry>
    </visual>
    <collision>
      <origin rpy="0 0 0" xyz="0 0 0"/>
      <geometry>
        <mesh filename="file://$(find quadruped_description)/meshes/aselsan/ROBOT_ABDUCTION_HL.stl"/>
      </geometry>
    </collision>
  </link>
  <joint name="comar/hip_4_joint" type="revolute">
    <limit effort="1000" lower="-3.1415" upper="3.1415" velocity="1000"/>
    <dynamics damping="0.03" friction="0.05"/>
    <origin rpy="1.5707845 -1.5707845 1.5707845" xyz="15.5e-3 0 -76.75e-3"/>
    <axis xyz="0 0 1"/>
    <parent link="comar/abad_4"/>
    <child link="comar/hip_4"/>
  </joint>
  <link name="comar/hip_4">
    <inertial>
      <origin xyz="26.4228e-3 3.0919e-3 54.0237e-3"/>
      <mass value="1.3625"/>
      <inertia ixx="5507.92e-6" ixy="-510892e-6" ixz="2820.18e-6" iyy="10901.5e-6" iyz="348021e-6" izz="6784.8e-6"/>
    </inertial>
    <visual>
      <origin rpy="0 0 0" xyz="0 0 0"/>
      <geometry>
        <mesh filename="file://$(find quadruped_description)/meshes/aselsan/ROBOT_HIP_L.stl"/>
      </geometry>
    </visual>
    <collision>
      <origin rpy="0 0 0" xyz="0 0 0"/>
      <geometry>
        <mesh filename="file://$(find quadruped_description)/meshes/aselsan/ROBOT_HIP_L.stl"/>
      </geometry>
    </collision>
  </link>
  <joint name="comar/knee_4_joint" type="revolute">
    <limit effort="0" lower="-3.1415" upper="3.1415" velocity="1000"/>
    <dynamics damping="0.03" friction="0.05"/>
    <origin rpy="0 0 0" xyz="200e-3 0 80.24e-3"/>
    <axis xyz="0 0 1"/>
    <parent link="comar/hip_4"/>
    <child link="comar/knee_4"/>
  </joint>
  <link name="comar/knee_4">
    <inertial>
      <origin xyz="138.023e-3 -7.0815e-3 0.9002e-3"/>
      <mass value="0.2967"/>
      <inertia ixx="71342e-6" ixy="294298e-6" ixz="-46.48e-6" iyy="7209.04e-6" iyz="2007e-6" izz="7242.60e-6"/>
    </inertial>
    <visual>
      <origin rpy="0 0 0" xyz="0 0 0"/>
      <geometry>
        <mesh filename="file://$(find quadruped_description)/meshes/aselsan/ROBOT_KNEE.stl"/>
      </geometry>
    </visual>
    <collision>
      <origin rpy="0 0 0" xyz="0 0 0"/>
      <geometry>
        <mesh filename="file://$(find quadruped_description)/meshes/aselsan/ROBOT_KNEE.stl"/>
      </geometry>
    </collision>
  </link>


  <!-- .............ABAD JOINTS............. -->

  <ros2_control name="comar/abad_1_joint" type="system">
    <hardware>
      <plugin>gazebo_ros2_control/GazeboSystem</plugin>
    </hardware>

    <joint name="comar/abad_1_joint">
      <command_interface name="effort"/>
      <state_interface name="position"/>
      <state_interface name="velocity"/>
    </joint>
  </ros2_control>

  <ros2_control name="comar/abad_2_joint" type="system">
    <hardware>
      <plugin>gazebo_ros2_control/GazeboSystem</plugin>
    </hardware>

    <joint name="comar/abad_2_joint">
      <command_interface name="effort"/>
      <state_interface name="position"/>
      <state_interface name="velocity"/>
    </joint>
  </ros2_control>

  <ros2_control name="comar/abad_3_joint" type="system">
    <hardware>
      <plugin>gazebo_ros2_control/GazeboSystem</plugin>
    </hardware>

    <joint name="comar/abad_3_joint">
      <command_interface name="effort"/>
      <state_interface name="position"/>
      <state_interface name="velocity"/>
    </joint>
  </ros2_control>

  <ros2_control name="comar/abad_4_joint" type="system">
    <hardware>
      <plugin>gazebo_ros2_control/GazeboSystem</plugin>
    </hardware>

    <joint name="comar/abad_4_joint">
      <command_interface name="effort"/>
      <state_interface name="position"/>
      <state_interface name="velocity"/>
    </joint>
  </ros2_control>

  <!-- .............HIP JOINTS............. -->

  <ros2_control name="comar/hip__joint" type="system">
    <hardware>
      <plugin>gazebo_ros2_control/GazeboSystem</plugin>
    </hardware>

    <joint name="comar/hip_1_joint">
      <command_interface name="effort"/>
      <state_interface name="position"/>
      <state_interface name="velocity"/>
    </joint>
  </ros2_control>

  <ros2_control name="comar/hip_2_joint" type="system">
    <hardware>
      <plugin>gazebo_ros2_control/GazeboSystem</plugin>
    </hardware>

    <joint name="comar/hip_2_joint">
      <command_interface name="effort"/>
      <state_interface name="position"/>
      <state_interface name="velocity"/>
    </joint>
  </ros2_control>

  <ros2_control name="comar/hip_3_joint" type="system">
    <hardware>
      <plugin>gazebo_ros2_control/GazeboSystem</plugin>
    </hardware>

    <joint name="comar/hip_3_joint">
      <command_interface name="effort"/>
      <state_interface name="position"/>
      <state_interface name="velocity"/>
    </joint>
  </ros2_control>

  <ros2_control name="comar/hip_4_joint" type="system">
    <hardware>
      <plugin>gazebo_ros2_control/GazeboSystem</plugin>
    </hardware>

    <joint name="comar/hip_4_joint">
      <command_interface name="effort"/>
      <state_interface name="position"/>
      <state_interface name="velocity"/>
    </joint>
  </ros2_control>

  <!-- .............CALF JOINTS............. -->

  <ros2_control name="comar/knee_1_joint" type="system">
    <hardware>
      <plugin>gazebo_ros2_control/GazeboSystem</plugin>
    </hardware>

    <joint name="comar/knee_1_joint">
      <command_interface name="effort"/>
      <state_interface name="position"/>
      <state_interface name="velocity"/>
    </joint>
  </ros2_control>

  <ros2_control name="comar/knee_2_joint" type="system">
    <hardware>
      <plugin>gazebo_ros2_control/GazeboSystem</plugin>
    </hardware>

    <joint name="comar/knee_2_joint">
      <command_interface name="effort"/>
      <state_interface name="position"/>
      <state_interface name="velocity"/>
    </joint>
  </ros2_control>

  <ros2_control name="comar/knee_3_joint" type="system">
    <hardware>
      <plugin>gazebo_ros2_control/GazeboSystem</plugin>
    </hardware>

    <joint name="comar/knee_3_joint">
      <command_interface name="effort"/>
      <state_interface name="position"/>
      <state_interface name="velocity"/>
    </joint>
  </ros2_control>

  <ros2_control name="comar/knee_4_joint" type="system">
    <hardware>
      <plugin>gazebo_ros2_control/GazeboSystem</plugin>
    </hardware>

    <joint name="comar/knee_4_joint">
      <command_interface name="effort"/>
      <state_interface name="position"/>
      <state_interface name="velocity"/>
    </joint>
  </ros2_control>

  <!-- .............GAZEBO............. -->
  
  <gazebo>
    <plugin filename="libgazebo_ros_p3d.so" name="p3d_base_controller">
      <ros>
        <!-- <namespace>/demo</namespace> -->
        <argument>odom:=odom/ground_truth</argument>
      </ros>
      <body_name>base</body_name>
      <frame_name>world</frame_name>
      <update_rate>250.0</update_rate>
      <xyz_offset>0 0 0</xyz_offset>
      <rpy_offset>0 0 0</rpy_offset>
      <gaussian_noise>0.01</gaussian_noise>
    </plugin>
  </gazebo>

  <gazebo>
    <plugin filename="libgazebo_ros2_control.so" name="gazebo_ros2_control">
      <parameters>$(find quadruped_gazebo)/config/aselsan_ros_control.yaml</parameters>
    </plugin>
  </gazebo>
</robot>

